[INFO] : 'Message '[336,{"as":[["40767.80000","5.29232966","1650349969.403835"],["40767.90000","3.87976490","1650349969.401403"],["40769.40000","0.11529840","1650349968.849888"],["40770.70000","0.48302214","1650349915.303057"],["40772.30000","0.73660000","1650349969.295069"],["40773.30000","0.18313532","1650349968.829215"],["40773.40000","6.13646452","1650349909.313383"],["40773.50000","0.67062773","1650349878.537112"],["40774.10000","0.30000000","1650349910.537702"],["40774.40000","1.98001829","1650349912.332739"]],"bs":[["40767.70000","0.46100000","1650349968.641367"],["40764.10000","0.19540000","1650349923.621889"],["40761.00000","0.57491423","1650349939.177783"],["40760.90000","0.23180000","1650349922.885453"],["40758.10000","0.60671369","1650349938.082873"],["40756.10000","0.00981596","1650349968.650960"],["40756.00000","3.68019615","1650349968.431877"],["40754.00000","0.56673232","1650349938.083306"],["40751.70000","0.02000000","1650349969.406170"],["40749.90000","0.57886321","1650349924.011907"]]},"book-10","XBT/USD"]' received at 2022-04-19T07:32:48.832875'
[INFO] : 'Message '[336,{"a":[["40767.80000","5.49232966","1650349969.894359"]],"c":"2153348542"},"book-10","XBT/USD"]' received at 2022-04-19T07:32:49.151529100'
[INFO] : 'Message '[336,{"b":[["40756.00000","0.00000000","1650349969.965706"],["40749.70000","0.02730000","1650349917.192047","r"]],"c":"1167247592"},"book-10","XBT/USD"]' received at 2022-04-19T07:32:49.226209100'
[INFO] : 'Message '[336,{"b":[["40757.00000","3.68010237","1650349970.017142"]],"c":"1863139325"},"book-10","XBT/USD"]' received at 2022-04-19T07:32:49.277113'
[INFO] : 'Message '[336,{"b":[["40756.10000","0.00000000","1650349970.124514"],["40749.70000","0.02730000","1650349917.192047","r"]],"c":"1013296148"},"book-10","XBT/USD"]' received at 2022-04-19T07:32:49.379876600'
[INFO] : 'Message '[336,{"b":[["40757.10000","0.00981596","1650349970.282352"]],"c":"1401126407"},"book-10","XBT/USD"]' received at 2022-04-19T07:32:49.537396800'
[INFO] : 'Message '[336,{"b":[["40757.00000","0.00000000","1650349970.513718"],["40749.70000","0.02730000","1650349917.192047","r"]],"c":"2364746157"},"book-10","XBT/USD"]' received at 2022-04-19T07:32:49.770476600'
[INFO] : 'Message '[336,{"b":[["40754.60000","3.68032553","1650349970.560937"]],"c":"1527533376"},"book-10","XBT/USD"]' received at 2022-04-19T07:32:49.815918600'
[INFO] : 'Message '[336,{"a":[["40767.80000","5.74232966","1650349970.563796"]],"c":"1603619879"},"book-10","XBT/USD"]' received at 2022-04-19T07:32:49.819981700'
[INFO] : 'Message '[336,{"a":[["40767.90000","3.67976490","1650349970.564720"]],"c":"2301330137"},"book-10","XBT/USD"]' received at 2022-04-19T07:32:49.823947300'
[INFO] : 'Message '[336,{"a":[["40767.80000","5.70537399","1650349970.580781"]],"c":"735529999"},"book-10","XBT/USD"]' received at 2022-04-19T07:32:49.835878200'
[INFO] : 'Message '[336,{"a":[["40768.00000","0.20000000","1650349970.604687"]],"c":"2249178534"},"book-10","XBT/USD"]' received at 2022-04-19T07:32:49.861887'
[INFO] : 'Message '[336,{"b":[["40757.10000","0.00000000","1650349970.669930"],["40749.70000","0.02730000","1650349917.192047","r"]],"c":"2116225142"},"book-10","XBT/USD"]' received at 2022-04-19T07:32:49.926473400'
[INFO] : 'Message '[336,{"b":[["40767.70000","0.27100000","1650349970.826094"]],"c":"3318045283"},"book-10","XBT/USD"]' received at 2022-04-19T07:32:50.082691600'
[INFO] : 'Message '[336,{"b":[["40754.70000","0.00981434","1650349970.830312"]],"c":"452730541"},"book-10","XBT/USD"]' received at 2022-04-19T07:32:50.085720600'
[INFO] : 'Message '[336,{"b":[["40754.60000","0.00000000","1650349972.234053"],["40749.70000","0.02730000","1650349917.192047","r"]],"c":"1942737851"},"book-10","XBT/USD"]' received at 2022-04-19T07:32:51.488920100'
[INFO] : 'Message '[336,{"b":[["40756.00000","3.68018605","1650349972.286737"]],"c":"3686476034"},"book-10","XBT/USD"]' received at 2022-04-19T07:32:51.541639500'
[INFO] : 'Message '[336,{"b":[["40754.70000","0.00000000","1650349972.429334"],["40749.70000","0.02730000","1650349917.192047","r"]],"c":"3182444597"},"book-10","XBT/USD"]' received at 2022-04-19T07:32:51.685193100'
[INFO] : 'Message '[336,{"a":[["40767.80000","5.19037399","1650349972.538099"]],"c":"2491379489"},"book-10","XBT/USD"]' received at 2022-04-19T07:32:51.794321900'
[INFO] : 'Message '[336,{"a":[["40773.30000","0.00000000","1650349972.563118"],["40774.40000","1.98001829","1650349912.332739","r"]],"c":"2676034800"},"book-10","XBT/USD"]' received at 2022-04-19T07:32:51.817809100'
[INFO] : 'Message '[336,{"b":[["40756.10000","0.00981434","1650349972.584590"]],"c":"861809348"},"book-10","XBT/USD"]' received at 2022-04-19T07:32:51.839388600'
[INFO] : 'Message '[336,{"a":[["40773.70000","0.00319600","1650349972.962998"]],"c":"1326095450"},"book-10","XBT/USD"]' received at 2022-04-19T07:32:52.219981200'
[INFO] : 'Message '[336,{"a":[["40769.40000","0.00000000","1650349973.143431"],["40774.40000","1.98001829","1650349912.332739","r"]],"c":"1577614836"},"book-10","XBT/USD"]' received at 2022-04-19T07:32:52.397923200'
[INFO] : 'Message '[336,{"a":[["40768.00000","0.00000000","1650349974.367230"],["40775.20000","0.33515208","1650349973.161281","r"]],"c":"3222251148"},"book-10","XBT/USD"]' received at 2022-04-19T07:32:53.625745300'
[INFO] : 'Message '[336,{"b":[["40756.00000","0.00000000","1650349974.514115"],["40749.70000","0.02730000","1650349917.192047","r"]],"c":"439796000"},"book-10","XBT/USD"]' received at 2022-04-19T07:32:53.784875100'
[INFO] : 'Message '[336,{"b":[["40753.80000","3.68040000","1650349974.563388"]],"c":"105559940"},"book-10","XBT/USD"]' received at 2022-04-19T07:32:53.819876'
[INFO] : 'Message '[336,{"a":[["40773.30000","0.18313532","1650349974.566279"]],"c":"4078859117"},"book-10","XBT/USD"]' received at 2022-04-19T07:32:53.821876300'
[INFO] : 'Message '[336,{"b":[["40756.10000","0.00000000","1650349974.673578"],["40749.70000","0.02730000","1650349917.192047","r"]],"c":"1400761348"},"book-10","XBT/USD"]' received at 2022-04-19T07:32:53.929877500'
[INFO] : 'Message '[336,{"b":[["40753.90000","0.00981421","1650349974.829469"]],"c":"1419547970"},"book-10","XBT/USD"]' received at 2022-04-19T07:32:54.084245700'
[INFO] : 'Message '[336,{"a":[["40767.80000","3.71835430","1650349976.640719"]],"c":"590924425"},"book-10","XBT/USD"]' received at 2022-04-19T07:32:55.896577400'
[INFO] : 'Message '[336,{"a":[["40767.80000","3.75498250","1650349977.347023"]],"c":"712700379"},"book-10","XBT/USD"]' received at 2022-04-19T07:32:56.602974500'
[INFO] : 'Message '[336,{"a":[["40767.80000","3.75485949","1650349977.824739"]],"c":"4102871613"},"book-10","XBT/USD"]' received at 2022-04-19T07:32:57.081387300'
[INFO] : 'Message '[336,{"a":[["40773.70000","0.00000000","1650349978.046987"],["40775.20000","0.33515208","1650349973.161281","r"]],"c":"4263334867"},"book-10","XBT/USD"]' received at 2022-04-19T07:32:57.301603100'
[INFO] : 'Message '[336,{"a":[["40767.80000","3.87015334","1650349978.612627"]],"c":"716148596"},"book-10","XBT/USD"]' received at 2022-04-19T07:32:57.868552900'
[INFO] : 'Message '[336,{"a":[["40767.80000","5.34224695","1650349978.616785"]],"c":"3813163624"},"book-10","XBT/USD"]' received at 2022-04-19T07:32:57.878556800'
[INFO] : 'Message '[336,{"b":[["40767.70000","0.46100000","1650349978.920141"]],"c":"240997597"},"book-10","XBT/USD"]' received at 2022-04-19T07:32:58.177850900'
[INFO] : 'Message '[336,{"b":[["40753.80000","0.00000000","1650349978.963746"],["40749.70000","0.02730000","1650349917.192047","r"]],"c":"2920817835"},"book-10","XBT/USD"]' received at 2022-04-19T07:32:58.219668100'
[INFO] : 'Message '[336,{"b":[["40755.40000","3.68024993","1650349979.010842"]],"c":"3533283668"},"book-10","XBT/USD"]' received at 2022-04-19T07:32:58.267719900'
[INFO] : 'Message '[336,{"b":[["40753.90000","0.00000000","1650349979.119741"],["40749.70000","0.02730000","1650349917.192047","r"]],"c":"1155831333"},"book-10","XBT/USD"]' received at 2022-04-19T07:32:58.377933800'
[INFO] : 'Message '[336,{"b":[["40767.70000","0.27100000","1650349979.268833"]],"c":"4278371376"},"book-10","XBT/USD"]' received at 2022-04-19T07:32:58.524605300'
[INFO] : 'Message '[336,{"b":[["40755.50000","0.00981447","1650349979.275066"]],"c":"2965016015"},"book-10","XBT/USD"]' received at 2022-04-19T07:32:58.531713100'
[INFO] : 'Message '[336,{"b":[["40755.40000","0.00000000","1650349980.150984"],["40749.70000","0.02730000","1650349917.192047","r"]],"c":"3971610136"},"book-10","XBT/USD"]' received at 2022-04-19T07:32:59.407510200'
[INFO] : 'Message '[336,{"b":[["40757.40000","3.68006107","1650349980.197483"]],"c":"2484390239"},"book-10","XBT/USD"]' received at 2022-04-19T07:32:59.456152700'
[INFO] : 'Message '[336,{"b":[["40755.50000","0.00000000","1650349980.306798"],["40749.70000","0.02730000","1650349917.192047","r"]],"c":"226910747"},"book-10","XBT/USD"]' received at 2022-04-19T07:32:59.562157500'
[INFO] : 'Message '[336,{"b":[["40757.50000","0.00981443","1650349980.462206"]],"c":"10432240"},"book-10","XBT/USD"]' received at 2022-04-19T07:32:59.716370100'
[INFO] : 'Message '[336,{"a":[["40767.80000","5.22695310","1650349982.223335"]],"c":"3227865461"},"book-10","XBT/USD"]' received at 2022-04-19T07:33:01.481482300'
[INFO] : 'Message '[336,{"a":[["40767.80000","3.75485949","1650349982.231062"]],"c":"499793739"},"book-10","XBT/USD"]' received at 2022-04-19T07:33:01.485493500'
[INFO] : 'Message '[336,{"a":[["40773.30000","0.00000000","1650349982.259882"],["40777.00000","0.12478244","1650349969.643921","r"]],"c":"2940154656"},"book-10","XBT/USD"]' received at 2022-04-19T07:33:01.513855900'
[INFO] : 'Message '[336,{"b":[["40757.40000","0.00000000","1650349983.888824"],["40749.70000","0.02730000","1650349917.192047","r"]],"c":"2011083679"},"book-10","XBT/USD"]' received at 2022-04-19T07:33:03.146096100'
[INFO] : 'Message '[336,{"b":[["40755.20000","3.68022736","1650349983.937256"]],"c":"567809268"},"book-10","XBT/USD"]' received at 2022-04-19T07:33:03.191065500'
[INFO] : 'Message '[336,{"b":[["40757.50000","0.00000000","1650349984.046384"],["40749.70000","0.02730000","1650349917.192047","r"]],"c":"1040155476"},"book-10","XBT/USD"]' received at 2022-04-19T07:33:03.302024700'
[INFO] : 'Message '[336,{"b":[["40755.30000","0.00981412","1650349984.203098"]],"c":"3145833429"},"book-10","XBT/USD"]' received at 2022-04-19T07:33:03.457926900'
[INFO] : 'Message '[336,{"a":[["40767.80000","5.22695296","1650349984.207007"]],"c":"218580134"},"book-10","XBT/USD"]' received at 2022-04-19T07:33:03.460950800'
[INFO] : 'Message '[336,{"a":[["40767.80000","5.55695296","1650349984.528475"]],"c":"1772457770"},"book-10","XBT/USD"]' received at 2022-04-19T07:33:03.783288700'
[INFO] : 'Message '[336,{"a":[["40767.80000","4.08485949","1650349985.530872"]],"c":"1660622331"},"book-10","XBT/USD"]' received at 2022-04-19T07:33:04.784729'
[INFO] : 'Message '[336,{"a":[["40767.80000","4.04823129","1650349985.581123"]],"c":"2309713824"},"book-10","XBT/USD"]' received at 2022-04-19T07:33:04.837728'
[INFO] : 'Message '[336,{"b":[["40767.70000","0.29246830","1650349987.647093"]],"c":"2995122379"},"book-10","XBT/USD"]' received at 2022-04-19T07:33:06.903150600'
[INFO] : 'Message '[336,{"a":[["40769.90000","0.11529213","1650349987.748680"]],"c":"235416384"},"book-10","XBT/USD"]' received at 2022-04-19T07:33:07.002223100'
[INFO] : 'Message '[336,{"a":[["40767.80000","4.08583085","1650349989.458377"]],"c":"1325587685"},"book-10","XBT/USD"]' received at 2022-04-19T07:33:08.816666400'
[INFO] : 'Message '[336,{"a":[["40774.50000","0.59855668","1650349990.261596"]],"c":"1937590929"},"book-10","XBT/USD"]' received at 2022-04-19T07:33:09.614043300'
[INFO] : 'Message '[336,{"a":[["40767.80000","5.55792421","1650349990.744726"]],"c":"553644019"},"book-10","XBT/USD"]' received at 2022-04-19T07:33:09.999932200'
[INFO] : 'Message '[336,{"a":[["40767.80000","4.08583085","1650349991.522921"]],"c":"1937590929"},"book-10","XBT/USD"]' received at 2022-04-19T07:33:10.824860400'
[INFO] : 'Message '[336,{"a":[["40769.90000","0.00000000","1650349992.814220"],["40775.20000","0.33515208","1650349973.161281","r"]],"c":"3094365789"},"book-10","XBT/USD"]' received at 2022-04-19T07:33:12.072552600'
[INFO] : 'Message '[336,{"a":[["40769.90000","0.11529219","1650349993.023022"]],"c":"299463890"},"book-10","XBT/USD"]' received at 2022-04-19T07:33:12.280816600'
[INFO] : 'Message '[336,{"b":[["40758.20000","0.00981437","1650349994.456095"]],"c":"924952251"},"book-10","XBT/USD"]' received at 2022-04-19T07:33:13.711110600'
[INFO] : 'Message '[336,{"b":[["40755.30000","0.00000000","1650349994.457281"],["40749.90000","0.57886321","1650349924.011907","r"]],"c":"619023180"},"book-10","XBT/USD"]' received at 2022-04-19T07:33:13.715076500'
[INFO] : 'Message '[336,{"b":[["40755.20000","0.00000000","1650349994.743773"],["40749.70000","0.02730000","1650349917.192047","r"]],"c":"1742775290"},"book-10","XBT/USD"]' received at 2022-04-19T07:33:14.003851600'
[INFO] : 'Message '[336,{"b":[["40757.10000","3.68017808","1650349994.790555"]],"c":"3587347017"},"book-10","XBT/USD"]' received at 2022-04-19T07:33:14.052275600'
[INFO] : 'Message '[336,{"a":[["40767.80000","3.75583085","1650349994.930217"]],"c":"212343911"},"book-10","XBT/USD"]' received at 2022-04-19T07:33:14.184817800'
[INFO] : 'Message '[336,{"a":[["40767.80000","3.75412571","1650349995.066248"]],"c":"1133393739"},"book-10","XBT/USD"]' received at 2022-04-19T07:33:14.325002600'
[INFO] : 'Message '[336,{"a":[["40773.30000","0.02000000","1650349995.096047"]],"c":"2188146841"},"book-10","XBT/USD"]' received at 2022-04-19T07:33:14.376510'
[INFO] : 'Message '[336,{"b":[["40751.70000","0.00000000","1650349995.096118"],["40749.70000","0.02730000","1650349917.192047","r"]],"c":"2558120936"},"book-10","XBT/USD"]' received at 2022-04-19T07:33:14.379577600'
[INFO] : 'Message '[336,{"a":[["40767.80000","2.77142571","1650349995.102193"]],"c":"2465077952"},"book-10","XBT/USD"]' received at 2022-04-19T07:33:14.381624800'
[INFO] : 'Message '[336,{"b":[["40757.10000","0.00000000","1650349995.109806"],["40748.10000","0.61051504","1650349970.015898","r"]],"c":"2105444648"},"book-10","XBT/USD"]' received at 2022-04-19T07:33:14.384631200'
[INFO] : 'Message '[336,{"a":[["40772.30000","0.00000000","1650349995.109970"],["40774.50000","0.59855668","1650349990.261596","r"]],"c":"9894562"},"book-10","XBT/USD"]' received at 2022-04-19T07:33:14.386615500'
[INFO] : 'Message '[336,{"a":[["40773.40000","0.00172965","1650349995.116037"]],"c":"305042131"},"book-10","XBT/USD"]' received at 2022-04-19T07:33:14.387616400'
[INFO] : 'Message '[336,{"b":[["40750.00000","0.01226993","1650349995.122269"]],"c":"2334559938"},"book-10","XBT/USD"]' received at 2022-04-19T07:33:14.389621900'
[INFO] : 'Message '[336,{"a":[["40769.90000","1.09799219","1650349995.147092"]],"c":"1289635140"},"book-10","XBT/USD"]' received at 2022-04-19T07:33:14.401815900'
[INFO] : 'Message '[336,{"b":[["40760.10000","3.67990650","1650349995.158137"]],"c":"3567095899"},"book-10","XBT/USD"]' received at 2022-04-19T07:33:14.412163100'
[INFO] : 'Message '[336,{"a":[["40767.90000","0.00000000","1650349995.162853"],["40777.10000","0.21203744","1650349905.132227","r"]],"c":"2208044638"},"book-10","XBT/USD"]' received at 2022-04-19T07:33:14.418160300'
[INFO] : 'Message '[336,{"a":[["40776.20000","0.73660000","1650349995.163764"]],"c":"2288276694"},"book-10","XBT/USD"]' received at 2022-04-19T07:33:14.421132800'
[INFO] : 'Message '[336,{"b":[["40760.10000","0.00000000","1650349995.210935"],["40749.70000","0.02730000","1650349917.192047","r"]],"c":"1039318816"},"book-10","XBT/USD"]' received at 2022-04-19T07:33:14.466659200'
[INFO] : 'Message '[336,{"a":[["40770.30000","3.67969820","1650349995.258308"]],"c":"3222195609"},"book-10","XBT/USD"]' received at 2022-04-19T07:33:14.527726800'
[INFO] : 'Message '[336,{"b":[["40750.00000","0.00000000","1650349995.302626"],["40748.10000","0.61051504","1650349970.015898","r"]],"c":"4007408364"},"book-10","XBT/USD"]' received at 2022-04-19T07:33:14.558919300'
[INFO] : 'Message '[336,{"a":[["40773.30000","0.00000000","1650349995.305119"],["40776.20000","0.73660000","1650349995.163764","r"]],"c":"3062635680"},"book-10","XBT/USD"]' received at 2022-04-19T07:33:14.561993600'
[INFO] : 'Message '[336,{"b":[["40757.20000","0.02000000","1650349995.305445"]],"c":"468383812"},"book-10","XBT/USD"]' received at 2022-04-19T07:33:14.565979100'
[INFO] : 'Message '[336,{"b":[["40758.20000","0.00000000","1650349995.312576"],["40748.10000","0.61051504","1650349970.015898","r"]],"c":"2164078690"},"book-10","XBT/USD"]' received at 2022-04-19T07:33:14.569987300'
[INFO] : 'Message '[336,{"b":[["40760.20000","0.00981413","1650349995.312927"]],"c":"522555120"},"book-10","XBT/USD"]' received at 2022-04-19T07:33:14.571985500'
[INFO] : 'Message '[336,{"b":[["40760.20000","0.00000000","1650349995.366349"],["40748.20000","0.01227048","1650349995.345426","r"]],"c":"1699942392"},"book-10","XBT/USD"]' received at 2022-04-19T07:33:14.621654700'
[INFO] : 'Message '[336,{"a":[["40769.90000","0.11529219","1650349995.419819"]],"c":"37884524"},"book-10","XBT/USD"]' received at 2022-04-19T07:33:14.678766500'
[INFO] : 'Message '[336,{"b":[["40748.20000","0.00000000","1650349995.419907"],["40748.10000","0.61051504","1650349970.015898","r"]],"c":"2012773922"},"book-10","XBT/USD"]' received at 2022-04-19T07:33:14.681798500'
[INFO] : 'Message '[336,{"b":[["40748.20000","0.01227048","1650349995.463922"]],"c":"37884524"},"book-10","XBT/USD"]' received at 2022-04-19T07:33:14.718230800'
[INFO] : 'Message '[336,{"a":[["40770.30000","0.00000000","1650349995.538450"],["40777.10000","0.21203744","1650349905.132227","r"]],"c":"111353715"},"book-10","XBT/USD"]' received at 2022-04-19T07:33:14.793467'
[INFO] : 'Message '[336,{"b":[["40758.20000","0.00981413","1650349995.548715"]],"c":"3144249991"},"book-10","XBT/USD"]' received at 2022-04-19T07:33:14.804044100'
[INFO] : 'Message '[336,{"b":[["40762.40000","3.67969820","1650349995.584976"]],"c":"2517902094"},"book-10","XBT/USD"]' received at 2022-04-19T07:33:14.840176400'
[INFO] : 'Message '[336,{"a":[["40769.10000","3.67979950","1650349995.585086"]],"c":"1839485397"},"book-10","XBT/USD"]' received at 2022-04-19T07:33:14.843278800'
[INFO] : 'Message '[336,{"b":[["40758.20000","0.00000000","1650349995.739795"],["40749.70000","0.02730000","1650349917.192047","r"]],"c":"1573771173"},"book-10","XBT/USD"]' received at 2022-04-19T07:33:14.994458500'
[INFO] : 'Message '[336,{"b":[["40762.50000","0.00981413","1650349995.740034"]],"c":"108250957"},"book-10","XBT/USD"]' received at 2022-04-19T07:33:14.997391600'
[INFO] : 'Message '[336,{"a":[["40775.00000","0.33515208","1650349995.999013"]],"c":"1197992319"},"book-10","XBT/USD"]' received at 2022-04-19T07:33:15.253008400'
[INFO] : 'Message '[336,{"b":[["40749.90000","0.00000000","1650349996.162816"],["40749.70000","0.02730000","1650349917.192047","r"]],"c":"2232470218"},"book-10","XBT/USD"]' received at 2022-04-19T07:33:15.419917900'
[INFO] : 'Message '[336,{"b":[["40762.20000","0.59711594","1650349996.162904"]],"c":"525456429"},"book-10","XBT/USD"]' received at 2022-04-19T07:33:15.421859900'
[INFO] : 'Message '[336,{"a":[["40767.80000","3.75412571","1650349996.207190"]],"c":"2861027878"},"book-10","XBT/USD"]' received at 2022-04-19T07:33:15.463660200'
[INFO] : 'Message '[336,{"b":[["40767.70000","0.51246830","1650349996.514712"]],"c":"1724745906"},"book-10","XBT/USD"]' received at 2022-04-19T07:33:15.770317300'
[INFO] : 'Message '[336,{"a":[["40769.10000","0.00000000","1650349996.516425"],["40776.20000","0.73660000","1650349995.163764","r"]],"c":"1009663278"},"book-10","XBT/USD"]' received at 2022-04-19T07:33:15.773422'
[INFO] : 'Message '[336,{"b":[["40762.40000","0.00000000","1650349996.516787"],["40749.70000","0.02730000","1650349917.192047","r"]],"c":"3551808615"},"book-10","XBT/USD"]' received at 2022-04-19T07:33:15.775413600'
[INFO] : 'Message '[336,{"a":[["40773.40000","0.73832965","1650349996.619999"]],"c":"2968544394"},"book-10","XBT/USD"]' received at 2022-04-19T07:33:15.875651300'
[INFO] : 'Message '[336,{"a":[["40776.20000","0.00000000","1650349996.623251"],["40777.10000","0.21203744","1650349905.132227","r"]],"c":"4097709181"},"book-10","XBT/USD"]' received at 2022-04-19T07:33:15.878636800'
[INFO] : 'Message '[336,{"b":[["40757.10000","3.68015888","1650349996.627513"]],"c":"2361926045"},"book-10","XBT/USD"]' received at 2022-04-19T07:33:15.882702200'
[INFO] : 'Message '[336,{"a":[["40767.80000","3.75402571","1650349996.649297"]],"c":"553536663"},"book-10","XBT/USD"]' received at 2022-04-19T07:33:15.907022100'
[INFO] : 'Message '[336,{"a":[["40767.80000","7.43418459","1650349996.675223"]],"c":"1125835845"},"book-10","XBT/USD"]' received at 2022-04-19T07:33:15.929571700'
[INFO] : 'Message '[336,{"a":[["40767.80000","8.90619162","1650349996.683815"]],"c":"4185007315"},"book-10","XBT/USD"]' received at 2022-04-19T07:33:15.939623300'
[INFO] : 'Message '[336,{"a":[["40767.80000","7.43418459","1650349996.725658"]],"c":"1125835845"},"book-10","XBT/USD"]' received at 2022-04-19T07:33:15.980847400'
[INFO] : 'Message '[336,{"a":[["40769.90000","0.00000000","1650349997.424843"],["40777.40000","0.02562168","1650349968.848203","r"]],"c":"3595463017"},"book-10","XBT/USD"]' received at 2022-04-19T07:33:16.681234600'
[INFO] : 'Message '[336,{"b":[["40767.70000","0.29246830","1650349998.158187"]],"c":"436483069"},"book-10","XBT/USD"]' received at 2022-04-19T07:33:17.413153900'
[INFO] : 'Message '[336,{"a":[["40767.80000","8.90617977","1650349998.751537"]],"c":"1834398418"},"book-10","XBT/USD"]' received at 2022-04-19T07:33:18.006116800'
[INFO] : 'Message '[336,{"b":[["40762.50000","0.00000000","1650349998.936107"],["40749.70000","0.02730000","1650349917.192047","r"]],"c":"7473063"},"book-10","XBT/USD"]' received at 2022-04-19T07:33:18.192773900'
[INFO] : 'Message '[336,{"b":[["40758.20000","0.00981400","1650349998.936616"]],"c":"606618556"},"book-10","XBT/USD"]' received at 2022-04-19T07:33:18.194742900'
